<?xml version="1.0"?>
<robot xmlns:xacro="http://www.ros.org/wiki/xacro" >

    <xacro:include filename="inertial_macros.xacro"/>

    <material name="white">
        <color rgba="1 1 1 1" />
    </material>

    <material name="pink">
        <color rgba="1 0.1 0.2 1"/>
    </material>

    <material name="blue">
        <color rgba="0.2 0.2 1 1"/>
    </material>

    <material name="black">
        <color rgba="0 0 0 1"/>
    </material>

    <!-- BASE LINK -->

    <link name="base_link">

    </link>


    <!-- CHASSIS LINK -->

     <joint name="chassis_joint" type="fixed">
        <parent link="base_link"/>
        <child link="chassis"/>
        <origin xyz="0 0 0"/>
    </joint>

    <link name="chassis">
        <visual>
            <origin xyz="0 0 0.11"/> <!-- połowa dlugosci chessis plis polowa kola 0.075 + 0.035-->
            <geometry>
                <box size="0.3 0.2 0.15"/>
            </geometry>
            <material name="white"/>
        </visual>
        <collision>
            <origin xyz="0 0 0.11"/>
            <geometry>
                <box size="0.3 0.2 0.15"/>
            </geometry>
        </collision>
        <xacro:inertial_box mass="0.5" x="0.3" y="0.2" z="0.15">
            <origin xyz="0 0 0.11" rpy="0 0 0"/>
        </xacro:inertial_box>
    </link>

    <gazebo reference="chassis">
        <material>Gazebo\Blue</material>
    </gazebo>
    
    <!-- LEFT DOWN WHEEL LINK -->

    <joint name="left_down_wheel_joint" type="continuous">
        <parent link="base_link"/>
        <child link="left_down_wheel"/>
        <origin xyz="-0.08 0.115 0.035" rpy="-${pi/2} 0 0" />
        <axis xyz="0 0 1"/>
    </joint>

    <link name="left_down_wheel">
        <visual>
            <geometry>
                <cylinder radius="0.035" length="0.03"/>
            </geometry>
            <material name="black"/>
        </visual>
        <collision>
            <geometry>
                <cylinder radius="0.035" length="0.03"/>
            </geometry>
        </collision>
        <xacro:inertial_cylinder mass="0.1" length="0.03" radius="0.035">
            <origin xyz="0 0 0" rpy="0 0 0"/>
        </xacro:inertial_cylinder>
    </link>

    <gazebo reference="left_down_wheel">
        <material>Gazebo\Black</material>
    </gazebo>

    <!-- RIGHT DOWN WHEEL LINK -->

    <joint name="right_down_wheel_joint" type="continuous">
        <parent link="base_link"/>
        <child link="right_down_wheel"/>
        <origin xyz="0.08 -0.115 0.035" rpy="${pi/2} 0 0" />
        <axis xyz="0 0 -1"/>
    </joint>

    <link name="right_down_wheel">
        <visual>
            <geometry>
                <cylinder radius="0.035" length="0.03"/>
            </geometry>
            <material name="black"/>
        </visual>
        <collision>
            <geometry>
                <cylinder radius="0.035" length="0.03"/>
            </geometry>
        </collision>
        <xacro:inertial_cylinder mass="0.1" length="0.03" radius="0.035">
            <origin xyz="0 0 0" rpy="0 0 0"/>
        </xacro:inertial_cylinder>
    </link>

    <gazebo reference="right_down_wheel">
        <material>Gazebo\Black</material>
    </gazebo>

    <!-- LEFT UP WHEEL LINK -->

    <joint name="left_up_wheel_joint" type="continuous">
        <parent link="base_link"/>
        <child link="left_up_wheel"/>
        <origin xyz="0.08 0.115 0.035" rpy="-${pi/2} 0 0" />
        <axis xyz="0 0 1"/>
    </joint>

    <link name="left_up_wheel">
        <visual>
            <geometry>
                <cylinder radius="0.035" length="0.03"/>
            </geometry>
            <material name="black"/>
        </visual>
        <collision>
            <geometry>
                <cylinder radius="0.035" length="0.03"/>
            </geometry>
        </collision>
        <xacro:inertial_cylinder mass="0.1" length="0.03" radius="0.035">
            <origin xyz="0 0 0" rpy="0 0 0"/>
        </xacro:inertial_cylinder>
    </link>


    <gazebo reference="left_up_wheel">
        <material>Gazebo\Black</material>
    </gazebo>

    <!-- RIGHT UP WHEEL LINK -->

    <joint name="right_up_wheel_joint" type="continuous">
        <parent link="base_link"/>
        <child link="right_up_wheel"/>
        <origin xyz="-0.08 -0.115 0.035" rpy="${pi/2} 0 0" />
        <axis xyz="0 0 -1"/>
    </joint>

    <link name="right_up_wheel">
        <visual>
            <geometry>
                <cylinder radius="0.035" length="0.03"/>
            </geometry>
            <material name="black"/>
        </visual>
        <collision>
            <geometry>
                <cylinder radius="0.035" length="0.03"/>
            </geometry>
        </collision>
        <xacro:inertial_cylinder mass="0.1" length="0.03" radius="0.035">
            <origin xyz="0 0 0" rpy="0 0 0"/>
        </xacro:inertial_cylinder>
    </link>

    <gazebo reference="right_up_wheel">
        <material>Gazebo\Black</material>
    </gazebo>
    
    
</robot>